Traceback (most recent call last):
  File "/scratch/c-aalag/uv-envs/language_model_rl/lib/python3.11/site-packages/huggingface_hub/utils/_http.py", line 409, in hf_raise_for_status
    response.raise_for_status()
  File "/scratch/c-aalag/uv-envs/language_model_rl/lib/python3.11/site-packages/requests/models.py", line 1024, in raise_for_status
    raise HTTPError(http_error_msg, response=self)
requests.exceptions.HTTPError: 401 Client Error: Unauthorized for url: https://huggingface.co/checkpoints/best_model/resolve/main/config.json

The above exception was the direct cause of the following exception:

Traceback (most recent call last):
  File "/scratch/c-aalag/uv-envs/language_model_rl/lib/python3.11/site-packages/transformers/utils/hub.py", line 470, in cached_files
    hf_hub_download(
  File "/scratch/c-aalag/uv-envs/language_model_rl/lib/python3.11/site-packages/huggingface_hub/utils/_validators.py", line 114, in _inner_fn
    return fn(*args, **kwargs)
           ^^^^^^^^^^^^^^^^^^^
  File "/scratch/c-aalag/uv-envs/language_model_rl/lib/python3.11/site-packages/huggingface_hub/file_download.py", line 1008, in hf_hub_download
    return _hf_hub_download_to_cache_dir(
           ^^^^^^^^^^^^^^^^^^^^^^^^^^^^^^
  File "/scratch/c-aalag/uv-envs/language_model_rl/lib/python3.11/site-packages/huggingface_hub/file_download.py", line 1115, in _hf_hub_download_to_cache_dir
    _raise_on_head_call_error(head_call_error, force_download, local_files_only)
  File "/scratch/c-aalag/uv-envs/language_model_rl/lib/python3.11/site-packages/huggingface_hub/file_download.py", line 1645, in _raise_on_head_call_error
    raise head_call_error
  File "/scratch/c-aalag/uv-envs/language_model_rl/lib/python3.11/site-packages/huggingface_hub/file_download.py", line 1533, in _get_metadata_or_catch_error
    metadata = get_hf_file_metadata(
               ^^^^^^^^^^^^^^^^^^^^^
  File "/scratch/c-aalag/uv-envs/language_model_rl/lib/python3.11/site-packages/huggingface_hub/utils/_validators.py", line 114, in _inner_fn
    return fn(*args, **kwargs)
           ^^^^^^^^^^^^^^^^^^^
  File "/scratch/c-aalag/uv-envs/language_model_rl/lib/python3.11/site-packages/huggingface_hub/file_download.py", line 1450, in get_hf_file_metadata
    r = _request_wrapper(
        ^^^^^^^^^^^^^^^^^
  File "/scratch/c-aalag/uv-envs/language_model_rl/lib/python3.11/site-packages/huggingface_hub/file_download.py", line 286, in _request_wrapper
    response = _request_wrapper(
               ^^^^^^^^^^^^^^^^^
  File "/scratch/c-aalag/uv-envs/language_model_rl/lib/python3.11/site-packages/huggingface_hub/file_download.py", line 310, in _request_wrapper
    hf_raise_for_status(response)
  File "/scratch/c-aalag/uv-envs/language_model_rl/lib/python3.11/site-packages/huggingface_hub/utils/_http.py", line 459, in hf_raise_for_status
    raise _format(RepositoryNotFoundError, message, response) from e
huggingface_hub.errors.RepositoryNotFoundError: 401 Client Error. (Request ID: Root=1-683f5301-5e99cf42315fff422ea8270f;9a3108a6-11f4-41f3-aba9-66018e25e308)

Repository Not Found for url: https://huggingface.co/checkpoints/best_model/resolve/main/config.json.
Please make sure you specified the correct `repo_id` and `repo_type`.
If you are trying to access a private or gated repo, make sure you are authenticated. For more details, see https://huggingface.co/docs/huggingface_hub/authentication
Invalid username or password.

The above exception was the direct cause of the following exception:

Traceback (most recent call last):
  File "/home/c-aalag/language_model_rl/rl_sft/rloo.py", line 154, in <module>
    train(args)
  File "/home/c-aalag/language_model_rl/rl_sft/rloo.py", line 82, in train
    model = AutoModelForCausalLM.from_pretrained(
            ^^^^^^^^^^^^^^^^^^^^^^^^^^^^^^^^^^^^^
  File "/scratch/c-aalag/uv-envs/language_model_rl/lib/python3.11/site-packages/transformers/models/auto/auto_factory.py", line 492, in from_pretrained
    resolved_config_file = cached_file(
                           ^^^^^^^^^^^^
  File "/scratch/c-aalag/uv-envs/language_model_rl/lib/python3.11/site-packages/transformers/utils/hub.py", line 312, in cached_file
    file = cached_files(path_or_repo_id=path_or_repo_id, filenames=[filename], **kwargs)
           ^^^^^^^^^^^^^^^^^^^^^^^^^^^^^^^^^^^^^^^^^^^^^^^^^^^^^^^^^^^^^^^^^^^^^^^^^^^^^
  File "/scratch/c-aalag/uv-envs/language_model_rl/lib/python3.11/site-packages/transformers/utils/hub.py", line 502, in cached_files
    raise OSError(
OSError: checkpoints/best_model is not a local folder and is not a valid model identifier listed on 'https://huggingface.co/models'
If this is a private repository, make sure to pass a token having permission to this repo either by logging in with `huggingface-cli login` or by passing `token=<your_token>`
Traceback (most recent call last):
  File "/scratch/c-aalag/uv-envs/language_model_rl/lib/python3.11/site-packages/huggingface_hub/utils/_http.py", line 409, in hf_raise_for_status
    response.raise_for_status()
  File "/scratch/c-aalag/uv-envs/language_model_rl/lib/python3.11/site-packages/requests/models.py", line 1024, in raise_for_status
    raise HTTPError(http_error_msg, response=self)
requests.exceptions.HTTPError: 401 Client Error: Unauthorized for url: https://huggingface.co/checkpoints/best_model/resolve/main/config.json

The above exception was the direct cause of the following exception:

Traceback (most recent call last):
  File "/scratch/c-aalag/uv-envs/language_model_rl/lib/python3.11/site-packages/transformers/utils/hub.py", line 470, in cached_files
    hf_hub_download(
  File "/scratch/c-aalag/uv-envs/language_model_rl/lib/python3.11/site-packages/huggingface_hub/utils/_validators.py", line 114, in _inner_fn
    return fn(*args, **kwargs)
           ^^^^^^^^^^^^^^^^^^^
  File "/scratch/c-aalag/uv-envs/language_model_rl/lib/python3.11/site-packages/huggingface_hub/file_download.py", line 1008, in hf_hub_download
    return _hf_hub_download_to_cache_dir(
           ^^^^^^^^^^^^^^^^^^^^^^^^^^^^^^
  File "/scratch/c-aalag/uv-envs/language_model_rl/lib/python3.11/site-packages/huggingface_hub/file_download.py", line 1115, in _hf_hub_download_to_cache_dir
    _raise_on_head_call_error(head_call_error, force_download, local_files_only)
  File "/scratch/c-aalag/uv-envs/language_model_rl/lib/python3.11/site-packages/huggingface_hub/file_download.py", line 1645, in _raise_on_head_call_error
    raise head_call_error
  File "/scratch/c-aalag/uv-envs/language_model_rl/lib/python3.11/site-packages/huggingface_hub/file_download.py", line 1533, in _get_metadata_or_catch_error
    metadata = get_hf_file_metadata(
               ^^^^^^^^^^^^^^^^^^^^^
  File "/scratch/c-aalag/uv-envs/language_model_rl/lib/python3.11/site-packages/huggingface_hub/utils/_validators.py", line 114, in _inner_fn
    return fn(*args, **kwargs)
           ^^^^^^^^^^^^^^^^^^^
  File "/scratch/c-aalag/uv-envs/language_model_rl/lib/python3.11/site-packages/huggingface_hub/file_download.py", line 1450, in get_hf_file_metadata
    r = _request_wrapper(
        ^^^^^^^^^^^^^^^^^
  File "/scratch/c-aalag/uv-envs/language_model_rl/lib/python3.11/site-packages/huggingface_hub/file_download.py", line 286, in _request_wrapper
    response = _request_wrapper(
               ^^^^^^^^^^^^^^^^^
  File "/scratch/c-aalag/uv-envs/language_model_rl/lib/python3.11/site-packages/huggingface_hub/file_download.py", line 310, in _request_wrapper
    hf_raise_for_status(response)
  File "/scratch/c-aalag/uv-envs/language_model_rl/lib/python3.11/site-packages/huggingface_hub/utils/_http.py", line 459, in hf_raise_for_status
    raise _format(RepositoryNotFoundError, message, response) from e
huggingface_hub.errors.RepositoryNotFoundError: 401 Client Error. (Request ID: Root=1-683f5301-5e99cf42315fff422ea8270f;9a3108a6-11f4-41f3-aba9-66018e25e308)

Repository Not Found for url: https://huggingface.co/checkpoints/best_model/resolve/main/config.json.
Please make sure you specified the correct `repo_id` and `repo_type`.
If you are trying to access a private or gated repo, make sure you are authenticated. For more details, see https://huggingface.co/docs/huggingface_hub/authentication
Invalid username or password.

The above exception was the direct cause of the following exception:

Traceback (most recent call last):
  File "/home/c-aalag/language_model_rl/rl_sft/rloo.py", line 154, in <module>
    train(args)
  File "/home/c-aalag/language_model_rl/rl_sft/rloo.py", line 82, in train
    model = AutoModelForCausalLM.from_pretrained(
            ^^^^^^^^^^^^^^^^^^^^^^^^^^^^^^^^^^^^^
  File "/scratch/c-aalag/uv-envs/language_model_rl/lib/python3.11/site-packages/transformers/models/auto/auto_factory.py", line 492, in from_pretrained
    resolved_config_file = cached_file(
                           ^^^^^^^^^^^^
  File "/scratch/c-aalag/uv-envs/language_model_rl/lib/python3.11/site-packages/transformers/utils/hub.py", line 312, in cached_file
    file = cached_files(path_or_repo_id=path_or_repo_id, filenames=[filename], **kwargs)
           ^^^^^^^^^^^^^^^^^^^^^^^^^^^^^^^^^^^^^^^^^^^^^^^^^^^^^^^^^^^^^^^^^^^^^^^^^^^^^
  File "/scratch/c-aalag/uv-envs/language_model_rl/lib/python3.11/site-packages/transformers/utils/hub.py", line 502, in cached_files
    raise OSError(
OSError: checkpoints/best_model is not a local folder and is not a valid model identifier listed on 'https://huggingface.co/models'
If this is a private repository, make sure to pass a token having permission to this repo either by logging in with `huggingface-cli login` or by passing `token=<your_token>`
